


  File "C:\Users\Nir\PycharmProjects\prooject_interview\.\api_integration.py", line 29, in send_to_google_gemini
    response.raise_for_status()
  File "C:\Users\Nir\PycharmProjects\prooject_interview\venv\lib\site-packages\requests\models.py", line 1024, in raise_for_status
    raise HTTPError(http_error_msg, response=self)
requests.exceptions.HTTPError: 404 Client Error: Not Found for url: https://api.google.com/gemini_endpoint
2024-07-18 09:11:32,874 - ImageApp - ERROR - Exception occurred: 404 Client Error: Not Found for url: https://api.google.com/gemini_endpoint
Traceback (most recent call last):
  File "C:\Users\Nir\PycharmProjects\prooject_interview\app.py", line 29, in <module>
    response = send_to_google_gemini(extracted_data)
  File "C:\Users\Nir\PycharmProjects\prooject_interview\.\api_integration.py", line 29, in send_to_google_gemini
    response.raise_for_status()


  File "C:\Users\Nir\PycharmProjects\prooject_interview\venv\lib\site-packages\requests\models.py", line 1024, in raise_for_status
    raise HTTPError(http_error_msg, response=self)
requests.exceptions.HTTPError: 404 Client Error: Not Found for url: https://api.google.com/gemini_endpoint
2024-07-18 09:11:32,874 - ImageApp - ERROR - Exception occurred: 404 Client Error: Not Found for url: https://api.google.com/gemini_endpoint
Traceback (most recent call last):
  File "C:\Users\Nir\PycharmProjects\prooject_interview\app.py", line 29, in <module>
    response = send_to_google_gemini(extracted_data)
  File "C:\Users\Nir\PycharmProjects\prooject_interview\.\api_integration.py", line 29, in send_to_google_gemini
    response.raise_for_status()
  File "C:\Users\Nir\PycharmProjects\prooject_interview\venv\lib\site-packages\requests\models.py", line 1024, in raise_for_status
    raise HTTPError(http_error_msg, response=self)
requests.exceptions.HTTPError: 404 Client Error: Not Found for url: https://api.google.com/gemini_endpoint
